Workbook

Sheet PEX
I2: PEX | AO2: SI | AS2: 00012345/25H
I3: Planejamento Executivo
AO4: Rev. PEX | AS4: 1
B6: 1. | D6: IDENTIFICAÇÃO DA INTERVENÇÃO
B8: Responsável | H8: DOUGLAS HIGINO DOS SANTOS | AA8: ID SAP (ou CPF): | AG8: =_xlfn.XLOOKUP(H8,Tabela6[Nome Completo],Tabela6[Matrícula SAP/ Documento],"",0) -> 268186 | AN8: Contato: | AR8: =_xlfn.XLOOKUP(H8,Tabela6[Nome Completo],Tabela6[Telefone],"",0) -> (85) 9.8109-8447
B9: Substituto | H9: DIEGO MAZZAGA ALMEIDA DE OLIVEIRA | AA9: ID SAP (ou CPF): | AG9: =_xlfn.XLOOKUP(H9,Tabela6[Nome Completo],Tabela6[Matrícula SAP/ Documento],"",0) -> 329170 | AN9: Contato: | AR9: =_xlfn.XLOOKUP(H9,Tabela6[Nome Completo],Tabela6[Telefone],"",0) -> (85) 9.8907-2573
B10: Fiscal Técnico | AA10: ID SAP (ou CPF): | AG10: =_xlfn.XLOOKUP(H10,Tabela6[Nome Completo],Tabela6[Matrícula SAP/ Documento],"",0) | AN10: Contato: | AR10: =_xlfn.XLOOKUP(H10,Tabela6[Nome Completo],Tabela6[Telefone],"",0)
B11: Coordenador | AA11: ID SAP (ou CPF): | AG11: =_xlfn.XLOOKUP(H11,Tabela6[Nome Completo],Tabela6[Matrícula SAP/ Documento],"",0) | AN11: Contato: | AR11: =_xlfn.XLOOKUP(H11,Tabela6[Nome Completo],Tabela6[Telefone],"",0)
B12: Técnico Seg. | AA12: ID SAP (ou CPF): | AG12: =_xlfn.XLOOKUP(H12,Tabela6[Nome Completo],Tabela6[Matrícula SAP/ Documento],"",0) | AN12: Contato: | AR12: =_xlfn.XLOOKUP(H12,Tabela6[Nome Completo],Tabela6[Telefone],"",0)
B13: Período | H13: 45996 | N13: 0.41666667 | Q13: a | R13: 45996 | X13: 0.47916667 | AA13: Periodicidade | AG13: FALSE | AH13: Contínuo | AM13: =IF(AG13=TRUE,FALSE,TRUE) -> TRUE | AN13: Diário
B14: Instalação | H14: BNB | M14: Equipamentos | S14: 34C1-5
B15: Resumo da Atividade | H15: Equipe OOTFB.C-SE, com apoio do O&M BNB, realizar correção de NCT crítica* na chave 34C1-5 BNB com LT 04C1 RSD/BNB desenergizada, isolada e aterrada. *NCT crítica documentada no RIT: OOTFB.C.247.2025. | BE15: =H15 -> Equipe OOTFB.C-SE, com apoio do O&M BNB, realizar correção de NCT crítica* na chave 34C1-5 BNB com LT 04C1 RSD/BNB desenergizada, isolada e aterrada. *NCT crítica documentada no RIT: OOTFB.C.247.2025.
B16: Configuração | H16: Recebimento:
H17: LT 04C1 BNB/RSD desenergizada, isolada e aterrada. # Terminal de BNB: - Disjuntor 14C1 aberto; - Chaves seccionadoras 34C1-4 e 34C1-5 abertas e bloqueadas; - Chave by-pass 34C1-6 aberta e bloqueada; - Lâmina de terra 34C1-7 fechada. # Terminal de RSD: - Disjuntor 14C1 aberto; - Chave seccionadora 34C1-5 aberta e bloqueada; - Chave by-pass 34C1-6 aberta e bloqueada; - Lâmina de terra 34C1-7 fechada. | BE17: =H17 -> LT 04C1 BNB/RSD desenergizada, isolada e aterrada. # Terminal de BNB: - Disjuntor 14C1 aberto; - Chaves seccionadoras 34C1-4 e 34C1-5 abertas e bloqueadas; - Chave by-pass 34C1-6 aberta e bloqueada; - Lâmina de terra 34C1-7 fechada. # Terminal de RSD: - Disjuntor 14C1 aberto; - Chave seccionadora 34C1-5 aberta e bloqueada; - Chave by-pass 34C1-6 aberta e bloqueada; - Lâmina de terra 34C1-7 fechada.
H18: Durante: | BE18: =H18 -> Durante:
H19: A chave seccionadora 34C1-5 BNB será manobrada durante a intervenção. | BE19: =H19 -> A chave seccionadora 34C1-5 BNB será manobrada durante a intervenção.
H20: Devolução: | BE20: =H20 -> Devolução:
H21: A chave 34C1-5 BNB pode ser devolvida fechada. Após a conclusão das atividades, a LT 04C1-BNB/RSD será energizada em teste antes da devolução para o ONS. | BE21: =H21 -> A chave 34C1-5 BNB pode ser devolvida fechada. Após a conclusão das atividades, a LT 04C1-BNB/RSD será energizada em teste antes da devolução para o ONS.
B22: Aterramento | H22: Durante a intervenção serão instalados os seguintes aterramentos móveis temporários: | BE22: =H22 -> Durante a intervenção serão instalados os seguintes aterramentos móveis temporários:
H23: - Nos pulos de interligação entre 34C1-5 e 94C1 (fases ABC); - Nos pulos de interligação entre 34C1-5 e 14C1 (fases ABC); | BE23: =H23 -> - Nos pulos de interligação entre 34C1-5 e 94C1 (fases ABC); - Nos pulos de interligação entre 34C1-5 e 14C1 (fases ABC);
H24: Total: 06 unidades | BE24: =H24 -> Total: 06 unidades
B25: Informações adicionais / Outras atividades previstas: | BE25: =I25 -> 0
C26: 1. Verificação das Configurações Prévias à Intervenção | BE26: =C26 -> 1. Verificação das Configurações Prévias à Intervenção
C27: As configurações necessárias para a intervenção estão descritas na "SI" e devem ser confirmadas por todos os envolvidos durante o recebimento (condições das chaves, disjuntores, pontos de aterramento, etc); | BE27: =C27 -> As configurações necessárias para a intervenção estão descritas na "SI" e devem ser confirmadas por todos os envolvidos durante o recebimento (condições das chaves, disjuntores, pontos de aterramento, etc);
C28: 2. Atenção à Distância de Segurança (D) | BE28: =C28 -> 2. Atenção à Distância de Segurança (D)
C29: É o afastamento mínimo no ar entre o trabalhador (ou suas ferramentas/instrumentos) e a parte energizada, de forma a evitar risco de descarga elétrica. | BE29: =C29 -> É o afastamento mínimo no ar entre o trabalhador (ou suas ferramentas/instrumentos) e a parte energizada, de forma a evitar risco de descarga elétrica.
C30: É calculada pela fórmula: D = d1 + d2 | BE30: =C30 -> É calculada pela fórmula: D = d1 + d2
C31: Onde: | BE31: =C31 -> Onde:
C32: d1 = Distância de Segurança Básica ou Valor de Base Menor distância em qualquer direção, entre executante dos trabalhos, inclusive suas ferramentas, e o ponto energizado mais próximo (tabela do Anexo I da NM-MN-SE-S.002). | BE32: =C32 -> d1 = Distância de Segurança Básica ou Valor de Base Menor distância em qualquer direção, entre executante dos trabalhos, inclusive suas ferramentas, e o ponto energizado mais próximo (tabela do Anexo I da NM-MN-SE-S.002).
C33: d2 = Distância de Segurança Variável: Distância requerida para movimentação do pessoal manipulando instrumentos ou ferramentas, sem invadir a distância d1. | BE33: =C33 -> d2 = Distância de Segurança Variável: Distância requerida para movimentação do pessoal manipulando instrumentos ou ferramentas, sem invadir a distância d1.
C34: Observação Importante: | BE34: =C34 -> Observação Importante:
C35: Devido à imprecisão dos movimentos humanos, recomenda-se acrescentar uma margem de segurança de pelo menos 50% sobre o valor de d2. | BE35: =C35 -> Devido à imprecisão dos movimentos humanos, recomenda-se acrescentar uma margem de segurança de pelo menos 50% sobre o valor de d2.
G36: Níveis de tensão fase-fase (kV) | T36: d1 (m) | AB36: d2+50% (m) | AJ36: D (m)
G37: 2,1 a 15,0 | T37: 0.65 | AB37: 1.65 | AJ37: 2.3
G38: 46,1 a 72,5 | T38: 0.95 | AB38: 1.65 | AJ38: 2.6
G39: 230,0 a 242,0 | T39: 1.55 | AB39: 1.65 | AJ39: 3.2
G40: 500,0 a 552,0 | T40: 3.4 | AB40: 1.65 | AJ40: 5.05
B42: 2. | D42: DADOS PARA PLANEJAMENTO DA INTERVENÇÃO
B44: Categoria | I44: Instruções / Detalhes | BD44: =B44 -> Categoria | BE44: =I44 -> Instruções / Detalhes
B45: Responsabilidade do Encarregado | I45: ▪ Avaliar o nível de prontidão física e emocional de todos os membros da equipe antes do início dos trabalhos; | BD45: =B45 -> Responsabilidade do Encarregado | BE45: =I45 -> ▪ Avaliar o nível de prontidão física e emocional de todos os membros da equipe antes do início dos trabalhos;
...

Sheet APR
D2: APR | J2: =PEX!AO2 -> SI | K2: =PEX!AS2 -> 00012345/25H
D3: Análise Preliminar de Riscos
J4: Rev. APR | K4: 1
B6: Este APR é anexo obrigatório ao Planejamento Executivo (PEX) da SI com numeração indicada acima. A ciência dos riscos identificados neste documento deve ser registrada na seção específica do PEX, mediante assinatura dos integrantes da equipe antes do início da atividade.
B8: IDENTIFICAÇÃO | G8: AVALIAÇÃO DE ACORDO COM A MATRIZ 5X5 | J8: HIERARQUIZAÇÃO DAS MEDIDAS DE CONTROLE | O8: STATUS APÓS AÇÕES E MEDIDAS
B9: ÁREA | C9: ATIVIDADE | D9: PERIGO | E9: DANOS / IMPACTO | F9: RISCO | G9: SEVERI-DADE | H9: PROBA-BILIDA-DE | I9: GRAU DE SIGNIFICÂNCIA (Risco) | J9: ELIMINAÇÃO | K9: SUBSTITUIÇÃO | L9: CONTROLES DE ENGENHARIA | M9: SINALIZAÇÃO/ ALERTAS E/OU CONTROLE ADM | N9: EPI | O9: SEVERI-DADE | P9: PROBA-BILIDA-DE | Q9: GRAU DE SIGNIFICÂNCIA (Risco) Após ações e medidas de controle | R9: CONTROLES ESPECÍFICOS
B10: Pátio 230kV | C10: Instalação de aterramento temporário | D10: =IF(Tabela1[[#This Row],[ATIVIDADE]]="","",_xlfn.XLOOKUP(Tabela1[[#This Row],[ATIVIDADE]],Tabela13[ATIVIDADE],Tabela13[PERIGO],"",0)) -> Eletricidade | E10: =IF(Tabela1[[#This Row],[ATIVIDADE]]="","",_xlfn.XLOOKUP(Tabela1[[#This Row],[ATIVIDADE]],Tabela13[ATIVIDADE],Tabela13[DANOS / IMPACTO],"",0)) -> Queimaduras, lesões graves ou fatais | F10: =IF(Tabela1[[#This Row],[ATIVIDADE]]="","",_xlfn.XLOOKUP(Tabela1[[#This Row],[ATIVIDADE]],Tabela13[ATIVIDADE],Tabela13[RISCO],"",0)) -> Choque elétrico | G10: =IF(Tabela1[[#This Row],[ATIVIDADE]]="","",_xlfn.XLOOKUP(Tabela1[[#This Row],[ATIVIDADE]],Tabela13[ATIVIDADE],Tabela13[SEVERI-DADE],"",0)) -> 5 | H10: =IF(Tabela1[[#This Row],[ATIVIDADE]]="","",_xlfn.XLOOKUP(Tabela1[[#This Row],[ATIVIDADE]],Tabela13[ATIVIDADE],Tabela13[PROBA-BILIDA-DE],"",0)) -> 4 | I10: =IFERROR(INDEX(Tabelas!$E$5:$I$9, MATCH(Tabela1[[#This Row],[PROBA-BILIDA-DE]], Tabelas!$D$5:$D$9, 0), MATCH(Tabela1[[#This Row],[SEVERI-DADE]], Tabelas!$E$4:$I$4, 0)),"") -> ⁴Muito Alto (20) | J10: =IF(Tabela1[[#This Row],[ATIVIDADE]]="","",_xlfn.XLOOKUP(Tabela1[[#This Row],[ATIVIDADE]],Tabela13[ATIVIDADE],Tabela13[ELIMINAÇÃO],"",0)) -> Desenergizar; teste de ausência de tensão | K10: =IF(Tabela1[[#This Row],[ATIVIDADE]]="","",_xlfn.XLOOKUP(Tabela1[[#This Row],[ATIVIDADE]],Tabela13[ATIVIDADE],Tabela13[SUBSTITUIÇÃO],"",0)) -> Sistemas automáticos de aterramento | L10: =IF(Tabela1[[#This Row],[ATIVIDADE]]="","",_xlfn.XLOOKUP(Tabela1[[#This Row],[ATIVIDADE]],Tabela13[ATIVIDADE],Tabela13[CONTROLES DE ENGENHARIA],"",0)) -> Dispositivo certificado; equipamento de teste | M10: =IF(Tabela1[[#This Row],[ATIVIDADE]]="","",_xlfn.XLOOKUP(Tabela1[[#This Row],[ATIVIDADE]],Tabela13[ATIVIDADE],Tabela13[SINALIZAÇÃO/ ALERTAS E/OU CONTROLE ADM],"",0)) -> Procedimento NR10; reciclagem periódica | N10: =IF(Tabela1[[#This Row],[ATIVIDADE]]="","",_xlfn.XLOOKUP(Tabela1[[#This Row],[ATIVIDADE]],Tabela13[ATIVIDADE],Tabela13[EPI],"",0)) -> Vestimenta anti-chama; capacete com viseira; luvas isolantes + sobreluvas mecânicas; bota isolante | O10: =IF(Tabela1[[#This Row],[ATIVIDADE]]="","",_xlfn.XLOOKUP(Tabela1[[#This Row],[ATIVIDADE]],Tabela13[ATIVIDADE],Tabela13[SEVERI-DADE ],"",0)) -> 5 | P10: =IF(Tabela1[[#This Row],[ATIVIDADE]]="","",_xlfn.XLOOKUP(Tabela1[[#This Row],[ATIVIDADE]],Tabela13[ATIVIDADE],Tabela13[PROBA-BILIDA-DE ],"",0)) -> 2 | Q10: =IFERROR(INDEX(Tabelas!$E$5:$I$9, MATCH(Tabela1[[#This Row],[PROBA-BILIDA-DE ]], Tabelas!$D$5:$D$9, 0), MATCH(Tabela1[[#This Row],[SEVERI-DADE ]], Tabelas!$E$4:$I$4, 0)),"") -> ³Alto (10) | R10: =IF(Tabela1[[#This Row],[ATIVIDADE]]="","",_xlfn.XLOOKUP(Tabela1[[#This Row],[ATIVIDADE]],Tabela13[ATIVIDADE],Tabela13[CONTROLES ESPECÍFICOS],"",0)) -> Testador de ausência de tensão
B11: Pátio 230kV | C11: Escalada no equipamento | D11: =IF(Tabela1[[#This Row],[ATIVIDADE]]="","",_xlfn.XLOOKUP(Tabela1[[#This Row],[ATIVIDADE]],Tabela13[ATIVIDADE],Tabela13[PERIGO],"",0)) -> Trabalho em altura | E11: =IF(Tabela1[[#This Row],[ATIVIDADE]]="","",_xlfn.XLOOKUP(Tabela1[[#This Row],[ATIVIDADE]],Tabela13[ATIVIDADE],Tabela13[DANOS / IMPACTO],"",0)) -> Fraturas, traumatismos, lesões graves ou fatais | F11: =IF(Tabela1[[#This Row],[ATIVIDADE]]="","",_xlfn.XLOOKUP(Tabela1[[#This Row],[ATIVIDADE]],Tabela13[ATIVIDADE],Tabela13[RISCO],"",0)) -> Queda de altura | G11: =IF(Tabela1[[#This Row],[ATIVIDADE]]="","",_xlfn.XLOOKUP(Tabela1[[#This Row],[ATIVIDADE]],Tabela13[ATIVIDADE],Tabela13[SEVERI-DADE],"",0)) -> 4 | H11: =IF(Tabela1[[#This Row],[ATIVIDADE]]="","",_xlfn.XLOOKUP(Tabela1[[#This Row],[ATIVIDADE]],Tabela13[ATIVIDADE],Tabela13[PROBA-BILIDA-DE],"",0)) -> 4 | I11: =IFERROR(INDEX(Tabelas!$E$5:$I$9, MATCH(Tabela1[[#This Row],[PROBA-BILIDA-DE]], Tabelas!$D$5:$D$9, 0), MATCH(Tabela1[[#This Row],[SEVERI-DADE]], Tabelas!$E$4:$I$4, 0)),"") -> ⁴Muito Alto (19) | J11: =IF(Tabela1[[#This Row],[ATIVIDADE]]="","",_xlfn.XLOOKUP(Tabela1[[#This Row],[ATIVIDADE]],Tabela13[ATIVIDADE],Tabela13[ELIMINAÇÃO],"",0)) -> Executar em solo quando possível (ferramentas longas, drones) | K11: =IF(Tabela1[[#This Row],[ATIVIDADE]]="","",_xlfn.XLOOKUP(Tabela1[[#This Row],[ATIVIDADE]],Tabela13[ATIVIDADE],Tabela13[SUBSTITUIÇÃO],"",0)) -> Plataformas elevatórias | L11: =IF(Tabela1[[#This Row],[ATIVIDADE]]="","",_xlfn.XLOOKUP(Tabela1[[#This Row],[ATIVIDADE]],Tabela13[ATIVIDADE],Tabela13[CONTROLES DE ENGENHARIA],"",0)) -> Linha de vida, pontos de ancoragem, guarda-corpos | M11: =IF(Tabela1[[#This Row],[ATIVIDADE]]="","",_xlfn.XLOOKUP(Tabela1[[#This Row],[ATIVIDADE]],Tabela13[ATIVIDADE],Tabela13[SINALIZAÇÃO/ ALERTAS E/OU CONTROLE ADM],"",0)) -> Procedimento NR35, checklist, controle de acesso | N11: =IF(Tabela1[[#This Row],[ATIVIDADE]]="","",_xlfn.XLOOKUP(Tabela1[[#This Row],[ATIVIDADE]],Tabela13[ATIVIDADE],Tabela13[EPI],"",0)) -> Cinturão paraquedista; trava-quedas retrátil; capacete com jugular; bota de segurança antiderrapante; luvas mecânicas | O11: =IF(Tabela1[[#This Row],[ATIVIDADE]]="","",_xlfn.XLOOKUP(Tabela1[[#This Row],[ATIVIDADE]],Tabela13[ATIVIDADE],Tabela13[SEVERI-DADE ],"",0)) -> 4 | P11: =IF(Tabela1[[#This Row],[ATIVIDADE]]="","",_xlfn.XLOOKUP(Tabela1[[#This Row],[ATIVIDADE]],Tabela13[ATIVIDADE],Tabela13[PROBA-BILIDA-DE ],"",0)) -> 2 | Q11: =IFERROR(INDEX(Tabelas!$E$5:$I$9, MATCH(Tabela1[[#This Row],[PROBA-BILIDA-DE ]], Tabelas!$D$5:$D$9, 0), MATCH(Tabela1[[#This Row],[SEVERI-DADE ]], Tabelas!$E$4:$I$4, 0)),"") -> ³Alto (9) | R11: =IF(Tabela1[[#This Row],[ATIVIDADE]]="","",_xlfn.XLOOKUP(Tabela1[[#This Row],[ATIVIDADE]],Tabela13[ATIVIDADE],Tabela13[CONTROLES ESPECÍFICOS],"",0)) -> - Inspeção prévia dos EPIs e pontos de ancoragem - Plano de resgate com equipe treinada - Uso de trava-quedas retrátil em linha vertical
B12: Pátio 230kV | C12: Confirmação da ausência de tensão | D12: =IF(Tabela1[[#This Row],[ATIVIDADE]]="","",_xlfn.XLOOKUP(Tabela1[[#This Row],[ATIVIDADE]],Tabela13[ATIVIDADE],Tabela13[PERIGO],"",0)) -> Eletricidade | E12: =IF(Tabela1[[#This Row],[ATIVIDADE]]="","",_xlfn.XLOOKUP(Tabela1[[#This Row],[ATIVIDADE]],Tabela13[ATIVIDADE],Tabela13[DANOS / IMPACTO],"",0)) -> Lesões graves ou fatais | F12: =IF(Tabela1[[#This Row],[ATIVIDADE]]="","",_xlfn.XLOOKUP(Tabela1[[#This Row],[ATIVIDADE]],Tabela13[ATIVIDADE],Tabela13[RISCO],"",0)) -> Choque elétrico | G12: =IF(Tabela1[[#This Row],[ATIVIDADE]]="","",_xlfn.XLOOKUP(Tabela1[[#This Row],[ATIVIDADE]],Tabela13[ATIVIDADE],Tabela13[SEVERI-DADE],"",0)) -> 5 | H12: =IF(Tabela1[[#This Row],[ATIVIDADE]]="","",_xlfn.XLOOKUP(Tabela1[[#This Row],[ATIVIDADE]],Tabela13[ATIVIDADE],Tabela13[PROBA-BILIDA-DE],"",0)) -> 3 | I12: =IFERROR(INDEX(Tabelas!$E$5:$I$9, MATCH(Tabela1[[#This Row],[PROBA-BILIDA-DE]], Tabelas!$D$5:$D$9, 0), MATCH(Tabela1[[#This Row],[SEVERI-DADE]], Tabelas!$E$4:$I$4, 0)),"") -> ⁴Muito Alto (15) | J12: =IF(Tabela1[[#This Row],[ATIVIDADE]]="","",_xlfn.XLOOKUP(Tabela1[[#This Row],[ATIVIDADE]],Tabela13[ATIVIDADE],Tabela13[ELIMINAÇÃO],"",0)) -> Evitar contato direto | K12: =IF(Tabela1[[#This Row],[ATIVIDADE]]="","",_xlfn.XLOOKUP(Tabela1[[#This Row],[ATIVIDADE]],Tabela13[ATIVIDADE],Tabela13[SUBSTITUIÇÃO],"",0)) -> NAPL | L12: =IF(Tabela1[[#This Row],[ATIVIDADE]]="","",_xlfn.XLOOKUP(Tabela1[[#This Row],[ATIVIDADE]],Tabela13[ATIVIDADE],Tabela13[CONTROLES DE ENGENHARIA],"",0)) -> Detector de tensão | M12: =IF(Tabela1[[#This Row],[ATIVIDADE]]="","",_xlfn.XLOOKUP(Tabela1[[#This Row],[ATIVIDADE]],Tabela13[ATIVIDADE],Tabela13[SINALIZAÇÃO/ ALERTAS E/OU CONTROLE ADM],"",0)) -> Procedimento NR10; aviso de teste | N12: =IF(Tabela1[[#This Row],[ATIVIDADE]]="","",_xlfn.XLOOKUP(Tabela1[[#This Row],[ATIVIDADE]],Tabela13[ATIVIDADE],Tabela13[EPI],"",0)) -> Vestimenta anti-chama; capacete com viseira; luvas isolantes + sobreluvas mecânicas; bota isolante | O12: =IF(Tabela1[[#This Row],[ATIVIDADE]]="","",_xlfn.XLOOKUP(Tabela1[[#This Row],[ATIVIDADE]],Tabela13[ATIVIDADE],Tabela13[SEVERI-DADE ],"",0)) -> 5 | P12: =IF(Tabela1[[#This Row],[ATIVIDADE]]="","",_xlfn.XLOOKUP(Tabela1[[#This Row],[ATIVIDADE]],Tabela13[ATIVIDADE],Tabela13[PROBA-BILIDA-DE ],"",0)) -> 1 | Q12: =IFERROR(INDEX(Tabelas!$E$5:$I$9, MATCH(Tabela1[[#This Row],[PROBA-BILIDA-DE ]], Tabelas!$D$5:$D$9, 0), MATCH(Tabela1[[#This Row],[SEVERI-DADE ]], Tabelas!$E$4:$I$4, 0)),"") -> ³Alto (5) | R12: =IF(Tabela1[[#This Row],[ATIVIDADE]]="","",_xlfn.XLOOKUP(Tabela1[[#This Row],[ATIVIDADE]],Tabela13[ATIVIDADE],Tabela13[CONTROLES ESPECÍFICOS],"",0)) -> Detector homologado, procedimento NR10
B13: Área externa | C13: Deslocamento de carro (colisão) | D13: =IF(Tabela1[[#This Row],[ATIVIDADE]]="","",_xlfn.XLOOKUP(Tabela1[[#This Row],[ATIVIDADE]],Tabela13[ATIVIDADE],Tabela13[PERIGO],"",0)) -> Veículo em movimento | E13: =IF(Tabela1[[#This Row],[ATIVIDADE]]="","",_xlfn.XLOOKUP(Tabela1[[#This Row],[ATIVIDADE]],Tabela13[ATIVIDADE],Tabela13[DANOS / IMPACTO],"",0)) -> Lesões graves, danos materiais | F13: =IF(Tabela1[[#This Row],[ATIVIDADE]]="","",_xlfn.XLOOKUP(Tabela1[[#This Row],[ATIVIDADE]],Tabela13[ATIVIDADE],Tabela13[RISCO],"",0)) -> Colisão | G13: =IF(Tabela1[[#This Row],[ATIVIDADE]]="","",_xlfn.XLOOKUP(Tabela1[[#This Row],[ATIVIDADE]],Tabela13[ATIVIDADE],Tabela13[SEVERI-DADE],"",0)) -> 4 | H13: =IF(Tabela1[[#This Row],[ATIVIDADE]]="","",_xlfn.XLOOKUP(Tabela1[[#This Row],[ATIVIDADE]],Tabela13[ATIVIDADE],Tabela13[PROBA-BILIDA-DE],"",0)) -> 3 | I13: =IFERROR(INDEX(Tabelas!$E$5:$I$9, MATCH(Tabela1[[#This Row],[PROBA-BILIDA-DE]], Tabelas!$D$5:$D$9, 0), MATCH(Tabela1[[#This Row],[SEVERI-DADE]], Tabelas!$E$4:$I$4, 0)),"") -> ³Alto (14) | J13: =IF(Tabela1[[#This Row],[ATIVIDADE]]="","",_xlfn.XLOOKUP(Tabela1[[#This Row],[ATIVIDADE]],Tabela13[ATIVIDADE],Tabela13[ELIMINAÇÃO],"",0)) -> Planejar rota | K13: =IF(Tabela1[[#This Row],[ATIVIDADE]]="","",_xlfn.XLOOKUP(Tabela1[[#This Row],[ATIVIDADE]],Tabela13[ATIVIDADE],Tabela13[SUBSTITUIÇÃO],"",0)) -> NAPL | L13: =IF(Tabela1[[#This Row],[ATIVIDADE]]="","",_xlfn.XLOOKUP(Tabela1[[#This Row],[ATIVIDADE]],Tabela13[ATIVIDADE],Tabela13[CONTROLES DE ENGENHARIA],"",0)) -> Limitação de velocidade; barreiras | M13: =IF(Tabela1[[#This Row],[ATIVIDADE]]="","",_xlfn.XLOOKUP(Tabela1[[#This Row],[ATIVIDADE]],Tabela13[ATIVIDADE],Tabela13[SINALIZAÇÃO/ ALERTAS E/OU CONTROLE ADM],"",0)) -> Sinalização de tráfego | N13: =IF(Tabela1[[#This Row],[ATIVIDADE]]="","",_xlfn.XLOOKUP(Tabela1[[#This Row],[ATIVIDADE]],Tabela13[ATIVIDADE],Tabela13[EPI],"",0)) -> Cinto de segurança | O13: =IF(Tabela1[[#This Row],[ATIVIDADE]]="","",_xlfn.XLOOKUP(Tabela1[[#This Row],[ATIVIDADE]],Tabela13[ATIVIDADE],Tabela13[SEVERI-DADE ],"",0)) -> 3 | P13: =IF(Tabela1[[#This Row],[ATIVIDADE]]="","",_xlfn.XLOOKUP(Tabela1[[#This Row],[ATIVIDADE]],Tabela13[ATIVIDADE],Tabela13[PROBA-BILIDA-DE ],"",0)) -> 1 | Q13: =IFERROR(INDEX(Tabelas!$E$5:$I$9, MATCH(Tabela1[[#This Row],[PROBA-BILIDA-DE ]], Tabelas!$D$5:$D$9, 0), MATCH(Tabela1[[#This Row],[SEVERI-DADE ]], Tabelas!$E$4:$I$4, 0)),"") -> ²Médio (3) | R13: =IF(Tabela1[[#This Row],[ATIVIDADE]]="","",_xlfn.XLOOKUP(Tabela1[[#This Row],[ATIVIDADE]],Tabela13[ATIVIDADE],Tabela13[CONTROLES ESPECÍFICOS],"",0)) -> Dirigir em baixa velocidade
B14: Área externa | C14: Deslocamento a pé (piso irregular) | D14: =IF(Tabela1[[#This Row],[ATIVIDADE]]="","",_xlfn.XLOOKUP(Tabela1[[#This Row],[ATIVIDADE]],Tabela13[ATIVIDADE],Tabela13[PERIGO],"",0)) -> Piso irregular | E14: =IF(Tabela1[[#This Row],[ATIVIDADE]]="","",_xlfn.XLOOKUP(Tabela1[[#This Row],[ATIVIDADE]],Tabela13[ATIVIDADE],Tabela13[DANOS / IMPACTO],"",0)) -> Escoriações, torções, fraturas leves | F14: =IF(Tabela1[[#This Row],[ATIVIDADE]]="","",_xlfn.XLOOKUP(Tabela1[[#This Row],[ATIVIDADE]],Tabela13[ATIVIDADE],Tabela13[RISCO],"",0)) -> Queda ao caminhar | G14: =IF(Tabela1[[#This Row],[ATIVIDADE]]="","",_xlfn.XLOOKUP(Tabela1[[#This Row],[ATIVIDADE]],Tabela13[ATIVIDADE],Tabela13[SEVERI-DADE],"",0)) -> 2 | H14: =IF(Tabela1[[#This Row],[ATIVIDADE]]="","",_xlfn.XLOOKUP(Tabela1[[#This Row],[ATIVIDADE]],Tabela13[ATIVIDADE],Tabela13[PROBA-BILIDA-DE],"",0)) -> 4 | I14: =IFERROR(INDEX(Tabelas!$E$5:$I$9, MATCH(Tabela1[[#This Row],[PROBA-BILIDA-DE]], Tabelas!$D$5:$D$9, 0), MATCH(Tabela1[[#This Row],[SEVERI-DADE]], Tabelas!$E$4:$I$4, 0)),"") -> ²Médio (17) | J14: =IF(Tabela1[[#This Row],[ATIVIDADE]]="","",_xlfn.XLOOKUP(Tabela1[[#This Row],[ATIVIDADE]],Tabela13[ATIVIDADE],Tabela13[ELIMINAÇÃO],"",0)) -> NAPL | K14: =IF(Tabela1[[#This Row],[ATIVIDADE]]="","",_xlfn.XLOOKUP(Tabela1[[#This Row],[ATIVIDADE]],Tabela13[ATIVIDADE],Tabela13[SUBSTITUIÇÃO],"",0)) -> NAPL | L14: =IF(Tabela1[[#This Row],[ATIVIDADE]]="","",_xlfn.XLOOKUP(Tabela1[[#This Row],[ATIVIDADE]],Tabela13[ATIVIDADE],Tabela13[CONTROLES DE ENGENHARIA],"",0)) -> Nivelamento de piso | M14: =IF(Tabela1[[#This Row],[ATIVIDADE]]="","",_xlfn.XLOOKUP(Tabela1[[#This Row],[ATIVIDADE]],Tabela13[ATIVIDADE],Tabela13[SINALIZAÇÃO/ ALERTAS E/OU CONTROLE ADM],"",0)) -> Inspeção visual; PEX/APR | N14: =IF(Tabela1[[#This Row],[ATIVIDADE]]="","",_xlfn.XLOOKUP(Tabela1[[#This Row],[ATIVIDADE]],Tabela13[ATIVIDADE],Tabela13[EPI],"",0)) -> Bota de segurança; capacete com jugular | O14: =IF(Tabela1[[#This Row],[ATIVIDADE]]="","",_xlfn.XLOOKUP(Tabela1[[#This Row],[ATIVIDADE]],Tabela13[ATIVIDADE],Tabela13[SEVERI-DADE ],"",0)) -> 2 | P14: =IF(Tabela1[[#This Row],[ATIVIDADE]]="","",_xlfn.XLOOKUP(Tabela1[[#This Row],[ATIVIDADE]],Tabela13[ATIVIDADE],Tabela13[PROBA-BILIDA-DE ],"",0)) -> 2 | Q14: =IFERROR(INDEX(Tabelas!$E$5:$I$9, MATCH(Tabela1[[#This Row],[PROBA-BILIDA-DE ]], Tabelas!$D$5:$D$9, 0), MATCH(Tabela1[[#This Row],[SEVERI-DADE ]], Tabelas!$E$4:$I$4, 0)),"") -> ¹Baixo (7) | R14: =IF(Tabela1[[#This Row],[ATIVIDADE]]="","",_xlfn.XLOOKUP(Tabela1[[#This Row],[ATIVIDADE]],Tabela13[ATIVIDADE],Tabela13[CONTROLES ESPECÍFICOS],"",0)) -> Movimentar-se atentamente
D15: =IF(Tabela1[[#This Row],[ATIVIDADE]]="","",_xlfn.XLOOKUP(Tabela1[[#This Row],[ATIVIDADE]],Tabela13[ATIVIDADE],Tabela13[PERIGO],"",0)) | E15: =IF(Tabela1[[#This Row],[ATIVIDADE]]="","",_xlfn.XLOOKUP(Tabela1[[#This Row],[ATIVIDADE]],Tabela13[ATIVIDADE],Tabela13[DANOS / IMPACTO],"",0)) | F15: =IF(Tabela1[[#This Row],[ATIVIDADE]]="","",_xlfn.XLOOKUP(Tabela1[[#This Row],[ATIVIDADE]],Tabela13[ATIVIDADE],Tabela13[RISCO],"",0)) | G15: =IF(Tabela1[[#This Row],[ATIVIDADE]]="","",_xlfn.XLOOKUP(Tabela1[[#This Row],[ATIVIDADE]],Tabela13[ATIVIDADE],Tabela13[SEVERI-DADE],"",0)) | H15: =IF(Tabela1[[#This Row],[ATIVIDADE]]="","",_xlfn.XLOOKUP(Tabela1[[#This Row],[ATIVIDADE]],Tabela13[ATIVIDADE],Tabela13[PROBA-BILIDA-DE],"",0)) | I15: =IFERROR(INDEX(Tabelas!$E$5:$I$9, MATCH(Tabela1[[#This Row],[PROBA-BILIDA-DE]], Tabelas!$D$5:$D$9, 0), MATCH(Tabela1[[#This Row],[SEVERI-DADE]], Tabelas!$E$4:$I$4, 0)),"") | J15: =IF(Tabela1[[#This Row],[ATIVIDADE]]="","",_xlfn.XLOOKUP(Tabela1[[#This Row],[ATIVIDADE]],Tabela13[ATIVIDADE],Tabela13[ELIMINAÇÃO],"",0)) | K15: =IF(Tabela1[[#This Row],[ATIVIDADE]]="","",_xlfn.XLOOKUP(Tabela1[[#This Row],[ATIVIDADE]],Tabela13[ATIVIDADE],Tabela13[SUBSTITUIÇÃO],"",0)) | L15: =IF(Tabela1[[#This Row],[ATIVIDADE]]="","",_xlfn.XLOOKUP(Tabela1[[#This Row],[ATIVIDADE]],Tabela13[ATIVIDADE],Tabela13[CONTROLES DE ENGENHARIA],"",0)) | M15: =IF(Tabela1[[#This Row],[ATIVIDADE]]="","",_xlfn.XLOOKUP(Tabela1[[#This Row],[ATIVIDADE]],Tabela13[ATIVIDADE],Tabela13[SINALIZAÇÃO/ ALERTAS E/OU CONTROLE ADM],"",0)) | N15: =IF(Tabela1[[#This Row],[ATIVIDADE]]="","",_xlfn.XLOOKUP(Tabela1[[#This Row],[ATIVIDADE]],Tabela13[ATIVIDADE],Tabela13[EPI],"",0)) | O15: =IF(Tabela1[[#This Row],[ATIVIDADE]]="","",_xlfn.XLOOKUP(Tabela1[[#This Row],[ATIVIDADE]],Tabela13[ATIVIDADE],Tabela13[SEVERI-DADE ],"",0)) | P15: =IF(Tabela1[[#This Row],[ATIVIDADE]]="","",_xlfn.XLOOKUP(Tabela1[[#This Row],[ATIVIDADE]],Tabela13[ATIVIDADE],Tabela13[PROBA-BILIDA-DE ],"",0)) | Q15: =IFERROR(INDEX(Tabelas!$E$5:$I$9, MATCH(Tabela1[[#This Row],[PROBA-BILIDA-DE ]], Tabelas!$D$5:$D$9, 0), MATCH(Tabela1[[#This Row],[SEVERI-DADE ]], Tabelas!$E$4:$I$4, 0)),"") | R15: =IF(Tabela1[[#This Row],[ATIVIDADE]]="","",_xlfn.XLOOKUP(Tabela1[[#This Row],[ATIVIDADE]],Tabela13[ATIVIDADE],Tabela13[CONTROLES ESPECÍFICOS],"",0))
D16: =IF(Tabela1[[#This Row],[ATIVIDADE]]="","",_xlfn.XLOOKUP(Tabela1[[#This Row],[ATIVIDADE]],Tabela13[ATIVIDADE],Tabela13[PERIGO],"",0)) | E16: =IF(Tabela1[[#This Row],[ATIVIDADE]]="","",_xlfn.XLOOKUP(Tabela1[[#This Row],[ATIVIDADE]],Tabela13[ATIVIDADE],Tabela13[DANOS / IMPACTO],"",0)) | F16: =IF(Tabela1[[#This Row],[ATIVIDADE]]="","",_xlfn.XLOOKUP(Tabela1[[#This Row],[ATIVIDADE]],Tabela13[ATIVIDADE],Tabela13[RISCO],"",0)) | G16: =IF(Tabela1[[#This Row],[ATIVIDADE]]="","",_xlfn.XLOOKUP(Tabela1[[#This Row],[ATIVIDADE]],Tabela13[ATIVIDADE],Tabela13[SEVERI-DADE],"",0)) | H16: =IF(Tabela1[[#This Row],[ATIVIDADE]]="","",_xlfn.XLOOKUP(Tabela1[[#This Row],[ATIVIDADE]],Tabela13[ATIVIDADE],Tabela13[PROBA-BILIDA-DE],"",0)) | I16: =IFERROR(INDEX(Tabelas!$E$5:$I$9, MATCH(Tabela1[[#This Row],[PROBA-BILIDA-DE]], Tabelas!$D$5:$D$9, 0), MATCH(Tabela1[[#This Row],[SEVERI-DADE]], Tabelas!$E$4:$I$4, 0)),"") | J16: =IF(Tabela1[[#This Row],[ATIVIDADE]]="","",_xlfn.XLOOKUP(Tabela1[[#This Row],[ATIVIDADE]],Tabela13[ATIVIDADE],Tabela13[ELIMINAÇÃO],"",0)) | K16: =IF(Tabela1[[#This Row],[ATIVIDADE]]="","",_xlfn.XLOOKUP(Tabela1[[#This Row],[ATIVIDADE]],Tabela13[ATIVIDADE],Tabela13[SUBSTITUIÇÃO],"",0)) | L16: =IF(Tabela1[[#This Row],[ATIVIDADE]]="","",_xlfn.XLOOKUP(Tabela1[[#This Row],[ATIVIDADE]],Tabela13[ATIVIDADE],Tabela13[CONTROLES DE ENGENHARIA],"",0)) | M16: =IF(Tabela1[[#This Row],[ATIVIDADE]]="","",_xlfn.XLOOKUP(Tabela1[[#This Row],[ATIVIDADE]],Tabela13[ATIVIDADE],Tabela13[SINALIZAÇÃO/ ALERTAS E/OU CONTROLE ADM],"",0)) | N16: =IF(Tabela1[[#This Row],[ATIVIDADE]]="","",_xlfn.XLOOKUP(Tabela1[[#This Row],[ATIVIDADE]],Tabela13[ATIVIDADE],Tabela13[EPI],"",0)) | O16: =IF(Tabela1[[#This Row],[ATIVIDADE]]="","",_xlfn.XLOOKUP(Tabela1[[#This Row],[ATIVIDADE]],Tabela13[ATIVIDADE],Tabela13[SEVERI-DADE ],"",0)) | P16: =IF(Tabela1[[#This Row],[ATIVIDADE]]="","",_xlfn.XLOOKUP(Tabela1[[#This Row],[ATIVIDADE]],Tabela13[ATIVIDADE],Tabela13[PROBA-BILIDA-DE ],"",0)) | Q16: =IFERROR(INDEX(Tabelas!$E$5:$I$9, MATCH(Tabela1[[#This Row],[PROBA-BILIDA-DE ]], Tabelas!$D$5:$D$9, 0), MATCH(Tabela1[[#This Row],[SEVERI-DADE ]], Tabelas!$E$4:$I$4, 0)),"") | R16: =IF(Tabela1[[#This Row],[ATIVIDADE]]="","",_xlfn.XLOOKUP(Tabela1[[#This Row],[ATIVIDADE]],Tabela13[ATIVIDADE],Tabela13[CONTROLES ESPECÍFICOS],"",0))
D17: =IF(Tabela1[[#This Row],[ATIVIDADE]]="","",_xlfn.XLOOKUP(Tabela1[[#This Row],[ATIVIDADE]],Tabela13[ATIVIDADE],Tabela13[PERIGO],"",0)) | E17: =IF(Tabela1[[#This Row],[ATIVIDADE]]="","",_xlfn.XLOOKUP(Tabela1[[#This Row],[ATIVIDADE]],Tabela13[ATIVIDADE],Tabela13[DANOS / IMPACTO],"",0)) | F17: =IF(Tabela1[[#This Row],[ATIVIDADE]]="","",_xlfn.XLOOKUP(Tabela1[[#This Row],[ATIVIDADE]],Tabela13[ATIVIDADE],Tabela13[RISCO],"",0)) | G17: =IF(Tabela1[[#This Row],[ATIVIDADE]]="","",_xlfn.XLOOKUP(Tabela1[[#This Row],[ATIVIDADE]],Tabela13[ATIVIDADE],Tabela13[SEVERI-DADE],"",0)) | H17: =IF(Tabela1[[#This Row],[ATIVIDADE]]="","",_xlfn.XLOOKUP(Tabela1[[#This Row],[ATIVIDADE]],Tabela13[ATIVIDADE],Tabela13[PROBA-BILIDA-DE],"",0)) | I17: =IFERROR(INDEX(Tabelas!$E$5:$I$9, MATCH(Tabela1[[#This Row],[PROBA-BILIDA-DE]], Tabelas!$D$5:$D$9, 0), MATCH(Tabela1[[#This Row],[SEVERI-DADE]], Tabelas!$E$4:$I$4, 0)),"") | J17: =IF(Tabela1[[#This Row],[ATIVIDADE]]="","",_xlfn.XLOOKUP(Tabela1[[#This Row],[ATIVIDADE]],Tabela13[ATIVIDADE],Tabela13[ELIMINAÇÃO],"",0)) | K17: =IF(Tabela1[[#This Row],[ATIVIDADE]]="","",_xlfn.XLOOKUP(Tabela1[[#This Row],[ATIVIDADE]],Tabela13[ATIVIDADE],Tabela13[SUBSTITUIÇÃO],"",0)) | L17: =IF(Tabela1[[#This Row],[ATIVIDADE]]="","",_xlfn.XLOOKUP(Tabela1[[#This Row],[ATIVIDADE]],Tabela13[ATIVIDADE],Tabela13[CONTROLES DE ENGENHARIA],"",0)) | M17: =IF(Tabela1[[#This Row],[ATIVIDADE]]="","",_xlfn.XLOOKUP(Tabela1[[#This Row],[ATIVIDADE]],Tabela13[ATIVIDADE],Tabela13[SINALIZAÇÃO/ ALERTAS E/OU CONTROLE ADM],"",0)) | N17: =IF(Tabela1[[#This Row],[ATIVIDADE]]="","",_xlfn.XLOOKUP(Tabela1[[#This Row],[ATIVIDADE]],Tabela13[ATIVIDADE],Tabela13[EPI],"",0)) | O17: =IF(Tabela1[[#This Row],[ATIVIDADE]]="","",_xlfn.XLOOKUP(Tabela1[[#This Row],[ATIVIDADE]],Tabela13[ATIVIDADE],Tabela13[SEVERI-DADE ],"",0)) | P17: =IF(Tabela1[[#This Row],[ATIVIDADE]]="","",_xlfn.XLOOKUP(Tabela1[[#This Row],[ATIVIDADE]],Tabela13[ATIVIDADE],Tabela13[PROBA-BILIDA-DE ],"",0)) | Q17: =IFERROR(INDEX(Tabelas!$E$5:$I$9, MATCH(Tabela1[[#This Row],[PROBA-BILIDA-DE ]], Tabelas!$D$5:$D$9, 0), MATCH(Tabela1[[#This Row],[SEVERI-DADE ]], Tabelas!$E$4:$I$4, 0)),"") | R17: =IF(Tabela1[[#This Row],[ATIVIDADE]]="","",_xlfn.XLOOKUP(Tabela1[[#This Row],[ATIVIDADE]],Tabela13[ATIVIDADE],Tabela13[CONTROLES ESPECÍFICOS],"",0))
D18: =IF(Tabela1[[#This Row],[ATIVIDADE]]="","",_xlfn.XLOOKUP(Tabela1[[#This Row],[ATIVIDADE]],Tabela13[ATIVIDADE],Tabela13[PERIGO],"",0)) | E18: =IF(Tabela1[[#This Row],[ATIVIDADE]]="","",_xlfn.XLOOKUP(Tabela1[[#This Row],[ATIVIDADE]],Tabela13[ATIVIDADE],Tabela13[DANOS / IMPACTO],"",0)) | F18: =IF(Tabela1[[#This Row],[ATIVIDADE]]="","",_xlfn.XLOOKUP(Tabela1[[#This Row],[ATIVIDADE]],Tabela13[ATIVIDADE],Tabela13[RISCO],"",0)) | G18: =IF(Tabela1[[#This Row],[ATIVIDADE]]="","",_xlfn.XLOOKUP(Tabela1[[#This Row],[ATIVIDADE]],Tabela13[ATIVIDADE],Tabela13[SEVERI-DADE],"",0)) | H18: =IF(Tabela1[[#This Row],[ATIVIDADE]]="","",_xlfn.XLOOKUP(Tabela1[[#This Row],[ATIVIDADE]],Tabela13[ATIVIDADE],Tabela13[PROBA-BILIDA-DE],"",0)) | I18: =IFERROR(INDEX(Tabelas!$E$5:$I$9, MATCH(Tabela1[[#This Row],[PROBA-BILIDA-DE]], Tabelas!$D$5:$D$9, 0), MATCH(Tabela1[[#This Row],[SEVERI-DADE]], Tabelas!$E$4:$I$4, 0)),"") | J18: =IF(Tabela1[[#This Row],[ATIVIDADE]]="","",_xlfn.XLOOKUP(Tabela1[[#This Row],[ATIVIDADE]],Tabela13[ATIVIDADE],Tabela13[ELIMINAÇÃO],"",0)) | K18: =IF(Tabela1[[#This Row],[ATIVIDADE]]="","",_xlfn.XLOOKUP(Tabela1[[#This Row],[ATIVIDADE]],Tabela13[ATIVIDADE],Tabela13[SUBSTITUIÇÃO],"",0)) | L18: =IF(Tabela1[[#This Row],[ATIVIDADE]]="","",_xlfn.XLOOKUP(Tabela1[[#This Row],[ATIVIDADE]],Tabela13[ATIVIDADE],Tabela13[CONTROLES DE ENGENHARIA],"",0)) | M18: =IF(Tabela1[[#This Row],[ATIVIDADE]]="","",_xlfn.XLOOKUP(Tabela1[[#This Row],[ATIVIDADE]],Tabela13[ATIVIDADE],Tabela13[SINALIZAÇÃO/ ALERTAS E/OU CONTROLE ADM],"",0)) | N18: =IF(Tabela1[[#This Row],[ATIVIDADE]]="","",_xlfn.XLOOKUP(Tabela1[[#This Row],[ATIVIDADE]],Tabela13[ATIVIDADE],Tabela13[EPI],"",0)) | O18: =IF(Tabela1[[#This Row],[ATIVIDADE]]="","",_xlfn.XLOOKUP(Tabela1[[#This Row],[ATIVIDADE]],Tabela13[ATIVIDADE],Tabela13[SEVERI-DADE ],"",0)) | P18: =IF(Tabela1[[#This Row],[ATIVIDADE]]="","",_xlfn.XLOOKUP(Tabela1[[#This Row],[ATIVIDADE]],Tabela13[ATIVIDADE],Tabela13[PROBA-BILIDA-DE ],"",0)) | Q18: =IFERROR(INDEX(Tabelas!$E$5:$I$9, MATCH(Tabela1[[#This Row],[PROBA-BILIDA-DE ]], Tabelas!$D$5:$D$9, 0), MATCH(Tabela1[[#This Row],[SEVERI-DADE ]], Tabelas!$E$4:$I$4, 0)),"") | R18: =IF(Tabela1[[#This Row],[ATIVIDADE]]="","",_xlfn.XLOOKUP(Tabela1[[#This Row],[ATIVIDADE]],Tabela13[ATIVIDADE],Tabela13[CONTROLES ESPECÍFICOS],"",0))
D19: =IF(Tabela1[[#This Row],[ATIVIDADE]]="","",_xlfn.XLOOKUP(Tabela1[[#This Row],[ATIVIDADE]],Tabela13[ATIVIDADE],Tabela13[PERIGO],"",0)) | E19: =IF(Tabela1[[#This Row],[ATIVIDADE]]="","",_xlfn.XLOOKUP(Tabela1[[#This Row],[ATIVIDADE]],Tabela13[ATIVIDADE],Tabela13[DANOS / IMPACTO],"",0)) | F19: =IF(Tabela1[[#This Row],[ATIVIDADE]]="","",_xlfn.XLOOKUP(Tabela1[[#This Row],[ATIVIDADE]],Tabela13[ATIVIDADE],Tabela13[RISCO],"",0)) | G19: =IF(Tabela1[[#This Row],[ATIVIDADE]]="","",_xlfn.XLOOKUP(Tabela1[[#This Row],[ATIVIDADE]],Tabela13[ATIVIDADE],Tabela13[SEVERI-DADE],"",0)) | H19: =IF(Tabela1[[#This Row],[ATIVIDADE]]="","",_xlfn.XLOOKUP(Tabela1[[#This Row],[ATIVIDADE]],Tabela13[ATIVIDADE],Tabela13[PROBA-BILIDA-DE],"",0)) | I19: =IFERROR(INDEX(Tabelas!$E$5:$I$9, MATCH(Tabela1[[#This Row],[PROBA-BILIDA-DE]], Tabelas!$D$5:$D$9, 0), MATCH(Tabela1[[#This Row],[SEVERI-DADE]], Tabelas!$E$4:$I$4, 0)),"") | J19: =IF(Tabela1[[#This Row],[ATIVIDADE]]="","",_xlfn.XLOOKUP(Tabela1[[#This Row],[ATIVIDADE]],Tabela13[ATIVIDADE],Tabela13[ELIMINAÇÃO],"",0)) | K19: =IF(Tabela1[[#This Row],[ATIVIDADE]]="","",_xlfn.XLOOKUP(Tabela1[[#This Row],[ATIVIDADE]],Tabela13[ATIVIDADE],Tabela13[SUBSTITUIÇÃO],"",0)) | L19: =IF(Tabela1[[#This Row],[ATIVIDADE]]="","",_xlfn.XLOOKUP(Tabela1[[#This Row],[ATIVIDADE]],Tabela13[ATIVIDADE],Tabela13[CONTROLES DE ENGENHARIA],"",0)) | M19: =IF(Tabela1[[#This Row],[ATIVIDADE]]="","",_xlfn.XLOOKUP(Tabela1[[#This Row],[ATIVIDADE]],Tabela13[ATIVIDADE],Tabela13[SINALIZAÇÃO/ ALERTAS E/OU CONTROLE ADM],"",0)) | N19: =IF(Tabela1[[#This Row],[ATIVIDADE]]="","",_xlfn.XLOOKUP(Tabela1[[#This Row],[ATIVIDADE]],Tabela13[ATIVIDADE],Tabela13[EPI],"",0)) | O19: =IF(Tabela1[[#This Row],[ATIVIDADE]]="","",_xlfn.XLOOKUP(Tabela1[[#This Row],[ATIVIDADE]],Tabela13[ATIVIDADE],Tabela13[SEVERI-DADE ],"",0)) | P19: =IF(Tabela1[[#This Row],[ATIVIDADE]]="","",_xlfn.XLOOKUP(Tabela1[[#This Row],[ATIVIDADE]],Tabela13[ATIVIDADE],Tabela13[PROBA-BILIDA-DE ],"",0)) | Q19: =IFERROR(INDEX(Tabelas!$E$5:$I$9, MATCH(Tabela1[[#This Row],[PROBA-BILIDA-DE ]], Tabelas!$D$5:$D$9, 0), MATCH(Tabela1[[#This Row],[SEVERI-DADE ]], Tabelas!$E$4:$I$4, 0)),"") | R19: =IF(Tabela1[[#This Row],[ATIVIDADE]]="","",_xlfn.XLOOKUP(Tabela1[[#This Row],[ATIVIDADE]],Tabela13[ATIVIDADE],Tabela13[CONTROLES ESPECÍFICOS],"",0))
D20: =IF(Tabela1[[#This Row],[ATIVIDADE]]="","",_xlfn.XLOOKUP(Tabela1[[#This Row],[ATIVIDADE]],Tabela13[ATIVIDADE],Tabela13[PERIGO],"",0)) | E20: =IF(Tabela1[[#This Row],[ATIVIDADE]]="","",_xlfn.XLOOKUP(Tabela1[[#This Row],[ATIVIDADE]],Tabela13[ATIVIDADE],Tabela13[DANOS / IMPACTO],"",0)) | F20: =IF(Tabela1[[#This Row],[ATIVIDADE]]="","",_xlfn.XLOOKUP(Tabela1[[#This Row],[ATIVIDADE]],Tabela13[ATIVIDADE],Tabela13[RISCO],"",0)) | G20: =IF(Tabela1[[#This Row],[ATIVIDADE]]="","",_xlfn.XLOOKUP(Tabela1[[#This Row],[ATIVIDADE]],Tabela13[ATIVIDADE],Tabela13[SEVERI-DADE],"",0)) | H20: =IF(Tabela1[[#This Row],[ATIVIDADE]]="","",_xlfn.XLOOKUP(Tabela1[[#This Row],[ATIVIDADE]],Tabela13[ATIVIDADE],Tabela13[PROBA-BILIDA-DE],"",0)) | I20: =IFERROR(INDEX(Tabelas!$E$5:$I$9, MATCH(Tabela1[[#This Row],[PROBA-BILIDA-DE]], Tabelas!$D$5:$D$9, 0), MATCH(Tabela1[[#This Row],[SEVERI-DADE]], Tabelas!$E$4:$I$4, 0)),"") | J20: =IF(Tabela1[[#This Row],[ATIVIDADE]]="","",_xlfn.XLOOKUP(Tabela1[[#This Row],[ATIVIDADE]],Tabela13[ATIVIDADE],Tabela13[ELIMINAÇÃO],"",0)) | K20: =IF(Tabela1[[#This Row],[ATIVIDADE]]="","",_xlfn.XLOOKUP(Tabela1[[#This Row],[ATIVIDADE]],Tabela13[ATIVIDADE],Tabela13[SUBSTITUIÇÃO],"",0)) | L20: =IF(Tabela1[[#This Row],[ATIVIDADE]]="","",_xlfn.XLOOKUP(Tabela1[[#This Row],[ATIVIDADE]],Tabela13[ATIVIDADE],Tabela13[CONTROLES DE ENGENHARIA],"",0)) | M20: =IF(Tabela1[[#This Row],[ATIVIDADE]]="","",_xlfn.XLOOKUP(Tabela1[[#This Row],[ATIVIDADE]],Tabela13[ATIVIDADE],Tabela13[SINALIZAÇÃO/ ALERTAS E/OU CONTROLE ADM],"",0)) | N20: =IF(Tabela1[[#This Row],[ATIVIDADE]]="","",_xlfn.XLOOKUP(Tabela1[[#This Row],[ATIVIDADE]],Tabela13[ATIVIDADE],Tabela13[EPI],"",0)) | O20: =IF(Tabela1[[#This Row],[ATIVIDADE]]="","",_xlfn.XLOOKUP(Tabela1[[#This Row],[ATIVIDADE]],Tabela13[ATIVIDADE],Tabela13[SEVERI-DADE ],"",0)) | P20: =IF(Tabela1[[#This Row],[ATIVIDADE]]="","",_xlfn.XLOOKUP(Tabela1[[#This Row],[ATIVIDADE]],Tabela13[ATIVIDADE],Tabela13[PROBA-BILIDA-DE ],"",0)) | Q20: =IFERROR(INDEX(Tabelas!$E$5:$I$9, MATCH(Tabela1[[#This Row],[PROBA-BILIDA-DE ]], Tabelas!$D$5:$D$9, 0), MATCH(Tabela1[[#This Row],[SEVERI-DADE ]], Tabelas!$E$4:$I$4, 0)),"") | R20: =IF(Tabela1[[#This Row],[ATIVIDADE]]="","",_xlfn.XLOOKUP(Tabela1[[#This Row],[ATIVIDADE]],Tabela13[ATIVIDADE],Tabela13[CONTROLES ESPECÍFICOS],"",0))
D21: =IF(Tabela1[[#This Row],[ATIVIDADE]]="","",_xlfn.XLOOKUP(Tabela1[[#This Row],[ATIVIDADE]],Tabela13[ATIVIDADE],Tabela13[PERIGO],"",0)) | E21: =IF(Tabela1[[#This Row],[ATIVIDADE]]="","",_xlfn.XLOOKUP(Tabela1[[#This Row],[ATIVIDADE]],Tabela13[ATIVIDADE],Tabela13[DANOS / IMPACTO],"",0)) | F21: =IF(Tabela1[[#This Row],[ATIVIDADE]]="","",_xlfn.XLOOKUP(Tabela1[[#This Row],[ATIVIDADE]],Tabela13[ATIVIDADE],Tabela13[RISCO],"",0)) | G21: =IF(Tabela1[[#This Row],[ATIVIDADE]]="","",_xlfn.XLOOKUP(Tabela1[[#This Row],[ATIVIDADE]],Tabela13[ATIVIDADE],Tabela13[SEVERI-DADE],"",0)) | H21: =IF(Tabela1[[#This Row],[ATIVIDADE]]="","",_xlfn.XLOOKUP(Tabela1[[#This Row],[ATIVIDADE]],Tabela13[ATIVIDADE],Tabela13[PROBA-BILIDA-DE],"",0)) | I21: =IFERROR(INDEX(Tabelas!$E$5:$I$9, MATCH(Tabela1[[#This Row],[PROBA-BILIDA-DE]], Tabelas!$D$5:$D$9, 0), MATCH(Tabela1[[#This Row],[SEVERI-DADE]], Tabelas!$E$4:$I$4, 0)),"") | J21: =IF(Tabela1[[#This Row],[ATIVIDADE]]="","",_xlfn.XLOOKUP(Tabela1[[#This Row],[ATIVIDADE]],Tabela13[ATIVIDADE],Tabela13[ELIMINAÇÃO],"",0)) | K21: =IF(Tabela1[[#This Row],[ATIVIDADE]]="","",_xlfn.XLOOKUP(Tabela1[[#This Row],[ATIVIDADE]],Tabela13[ATIVIDADE],Tabela13[SUBSTITUIÇÃO],"",0)) | L21: =IF(Tabela1[[#This Row],[ATIVIDADE]]="","",_xlfn.XLOOKUP(Tabela1[[#This Row],[ATIVIDADE]],Tabela13[ATIVIDADE],Tabela13[CONTROLES DE ENGENHARIA],"",0)) | M21: =IF(Tabela1[[#This Row],[ATIVIDADE]]="","",_xlfn.XLOOKUP(Tabela1[[#This Row],[ATIVIDADE]],Tabela13[ATIVIDADE],Tabela13[SINALIZAÇÃO/ ALERTAS E/OU CONTROLE ADM],"",0)) | N21: =IF(Tabela1[[#This Row],[ATIVIDADE]]="","",_xlfn.XLOOKUP(Tabela1[[#This Row],[ATIVIDADE]],Tabela13[ATIVIDADE],Tabela13[EPI],"",0)) | O21: =IF(Tabela1[[#This Row],[ATIVIDADE]]="","",_xlfn.XLOOKUP(Tabela1[[#This Row],[ATIVIDADE]],Tabela13[ATIVIDADE],Tabela13[SEVERI-DADE ],"",0)) | P21: =IF(Tabela1[[#This Row],[ATIVIDADE]]="","",_xlfn.XLOOKUP(Tabela1[[#This Row],[ATIVIDADE]],Tabela13[ATIVIDADE],Tabela13[PROBA-BILIDA-DE ],"",0)) | Q21: =IFERROR(INDEX(Tabelas!$E$5:$I$9, MATCH(Tabela1[[#This Row],[PROBA-BILIDA-DE ]], Tabelas!$D$5:$D$9, 0), MATCH(Tabela1[[#This Row],[SEVERI-DADE ]], Tabelas!$E$4:$I$4, 0)),"") | R21: =IF(Tabela1[[#This Row],[ATIVIDADE]]="","",_xlfn.XLOOKUP(Tabela1[[#This Row],[ATIVIDADE]],Tabela13[ATIVIDADE],Tabela13[CONTROLES ESPECÍFICOS],"",0))
D22: =IF(Tabela1[[#This Row],[ATIVIDADE]]="","",_xlfn.XLOOKUP(Tabela1[[#This Row],[ATIVIDADE]],Tabela13[ATIVIDADE],Tabela13[PERIGO],"",0)) | E22: =IF(Tabela1[[#This Row],[ATIVIDADE]]="","",_xlfn.XLOOKUP(Tabela1[[#This Row],[ATIVIDADE]],Tabela13[ATIVIDADE],Tabela13[DANOS / IMPACTO],"",0)) | F22: =IF(Tabela1[[#This Row],[ATIVIDADE]]="","",_xlfn.XLOOKUP(Tabela1[[#This Row],[ATIVIDADE]],Tabela13[ATIVIDADE],Tabela13[RISCO],"",0)) | G22: =IF(Tabela1[[#This Row],[ATIVIDADE]]="","",_xlfn.XLOOKUP(Tabela1[[#This Row],[ATIVIDADE]],Tabela13[ATIVIDADE],Tabela13[SEVERI-DADE],"",0)) | H22: =IF(Tabela1[[#This Row],[ATIVIDADE]]="","",_xlfn.XLOOKUP(Tabela1[[#This Row],[ATIVIDADE]],Tabela13[ATIVIDADE],Tabela13[PROBA-BILIDA-DE],"",0)) | I22: =IFERROR(INDEX(Tabelas!$E$5:$I$9, MATCH(Tabela1[[#This Row],[PROBA-BILIDA-DE]], Tabelas!$D$5:$D$9, 0), MATCH(Tabela1[[#This Row],[SEVERI-DADE]], Tabelas!$E$4:$I$4, 0)),"") | J22: =IF(Tabela1[[#This Row],[ATIVIDADE]]="","",_xlfn.XLOOKUP(Tabela1[[#This Row],[ATIVIDADE]],Tabela13[ATIVIDADE],Tabela13[ELIMINAÇÃO],"",0)) | K22: =IF(Tabela1[[#This Row],[ATIVIDADE]]="","",_xlfn.XLOOKUP(Tabela1[[#This Row],[ATIVIDADE]],Tabela13[ATIVIDADE],Tabela13[SUBSTITUIÇÃO],"",0)) | L22: =IF(Tabela1[[#This Row],[ATIVIDADE]]="","",_xlfn.XLOOKUP(Tabela1[[#This Row],[ATIVIDADE]],Tabela13[ATIVIDADE],Tabela13[CONTROLES DE ENGENHARIA],"",0)) | M22: =IF(Tabela1[[#This Row],[ATIVIDADE]]="","",_xlfn.XLOOKUP(Tabela1[[#This Row],[ATIVIDADE]],Tabela13[ATIVIDADE],Tabela13[SINALIZAÇÃO/ ALERTAS E/OU CONTROLE ADM],"",0)) | N22: =IF(Tabela1[[#This Row],[ATIVIDADE]]="","",_xlfn.XLOOKUP(Tabela1[[#This Row],[ATIVIDADE]],Tabela13[ATIVIDADE],Tabela13[EPI],"",0)) | O22: =IF(Tabela1[[#This Row],[ATIVIDADE]]="","",_xlfn.XLOOKUP(Tabela1[[#This Row],[ATIVIDADE]],Tabela13[ATIVIDADE],Tabela13[SEVERI-DADE ],"",0)) | P22: =IF(Tabela1[[#This Row],[ATIVIDADE]]="","",_xlfn.XLOOKUP(Tabela1[[#This Row],[ATIVIDADE]],Tabela13[ATIVIDADE],Tabela13[PROBA-BILIDA-DE ],"",0)) | Q22: =IFERROR(INDEX(Tabelas!$E$5:$I$9, MATCH(Tabela1[[#This Row],[PROBA-BILIDA-DE ]], Tabelas!$D$5:$D$9, 0), MATCH(Tabela1[[#This Row],[SEVERI-DADE ]], Tabelas!$E$4:$I$4, 0)),"") | R22: =IF(Tabela1[[#This Row],[ATIVIDADE]]="","",_xlfn.XLOOKUP(Tabela1[[#This Row],[ATIVIDADE]],Tabela13[ATIVIDADE],Tabela13[CONTROLES ESPECÍFICOS],"",0))
D23: =IF(Tabela1[[#This Row],[ATIVIDADE]]="","",_xlfn.XLOOKUP(Tabela1[[#This Row],[ATIVIDADE]],Tabela13[ATIVIDADE],Tabela13[PERIGO],"",0)) | E23: =IF(Tabela1[[#This Row],[ATIVIDADE]]="","",_xlfn.XLOOKUP(Tabela1[[#This Row],[ATIVIDADE]],Tabela13[ATIVIDADE],Tabela13[DANOS / IMPACTO],"",0)) | F23: =IF(Tabela1[[#This Row],[ATIVIDADE]]="","",_xlfn.XLOOKUP(Tabela1[[#This Row],[ATIVIDADE]],Tabela13[ATIVIDADE],Tabela13[RISCO],"",0)) | G23: =IF(Tabela1[[#This Row],[ATIVIDADE]]="","",_xlfn.XLOOKUP(Tabela1[[#This Row],[ATIVIDADE]],Tabela13[ATIVIDADE],Tabela13[SEVERI-DADE],"",0)) | H23: =IF(Tabela1[[#This Row],[ATIVIDADE]]="","",_xlfn.XLOOKUP(Tabela1[[#This Row],[ATIVIDADE]],Tabela13[ATIVIDADE],Tabela13[PROBA-BILIDA-DE],"",0)) | I23: =IFERROR(INDEX(Tabelas!$E$5:$I$9, MATCH(Tabela1[[#This Row],[PROBA-BILIDA-DE]], Tabelas!$D$5:$D$9, 0), MATCH(Tabela1[[#This Row],[SEVERI-DADE]], Tabelas!$E$4:$I$4, 0)),"") | J23: =IF(Tabela1[[#This Row],[ATIVIDADE]]="","",_xlfn.XLOOKUP(Tabela1[[#This Row],[ATIVIDADE]],Tabela13[ATIVIDADE],Tabela13[ELIMINAÇÃO],"",0)) | K23: =IF(Tabela1[[#This Row],[ATIVIDADE]]="","",_xlfn.XLOOKUP(Tabela1[[#This Row],[ATIVIDADE]],Tabela13[ATIVIDADE],Tabela13[SUBSTITUIÇÃO],"",0)) | L23: =IF(Tabela1[[#This Row],[ATIVIDADE]]="","",_xlfn.XLOOKUP(Tabela1[[#This Row],[ATIVIDADE]],Tabela13[ATIVIDADE],Tabela13[CONTROLES DE ENGENHARIA],"",0)) | M23: =IF(Tabela1[[#This Row],[ATIVIDADE]]="","",_xlfn.XLOOKUP(Tabela1[[#This Row],[ATIVIDADE]],Tabela13[ATIVIDADE],Tabela13[SINALIZAÇÃO/ ALERTAS E/OU CONTROLE ADM],"",0)) | N23: =IF(Tabela1[[#This Row],[ATIVIDADE]]="","",_xlfn.XLOOKUP(Tabela1[[#This Row],[ATIVIDADE]],Tabela13[ATIVIDADE],Tabela13[EPI],"",0)) | O23: =IF(Tabela1[[#This Row],[ATIVIDADE]]="","",_xlfn.XLOOKUP(Tabela1[[#This Row],[ATIVIDADE]],Tabela13[ATIVIDADE],Tabela13[SEVERI-DADE ],"",0)) | P23: =IF(Tabela1[[#This Row],[ATIVIDADE]]="","",_xlfn.XLOOKUP(Tabela1[[#This Row],[ATIVIDADE]],Tabela13[ATIVIDADE],Tabela13[PROBA-BILIDA-DE ],"",0)) | Q23: =IFERROR(INDEX(Tabelas!$E$5:$I$9, MATCH(Tabela1[[#This Row],[PROBA-BILIDA-DE ]], Tabelas!$D$5:$D$9, 0), MATCH(Tabela1[[#This Row],[SEVERI-DADE ]], Tabelas!$E$4:$I$4, 0)),"") | R23: =IF(Tabela1[[#This Row],[ATIVIDADE]]="","",_xlfn.XLOOKUP(Tabela1[[#This Row],[ATIVIDADE]],Tabela13[ATIVIDADE],Tabela13[CONTROLES ESPECÍFICOS],"",0))
D24: =IF(Tabela1[[#This Row],[ATIVIDADE]]="","",_xlfn.XLOOKUP(Tabela1[[#This Row],[ATIVIDADE]],Tabela13[ATIVIDADE],Tabela13[PERIGO],"",0)) | E24: =IF(Tabela1[[#This Row],[ATIVIDADE]]="","",_xlfn.XLOOKUP(Tabela1[[#This Row],[ATIVIDADE]],Tabela13[ATIVIDADE],Tabela13[DANOS / IMPACTO],"",0)) | F24: =IF(Tabela1[[#This Row],[ATIVIDADE]]="","",_xlfn.XLOOKUP(Tabela1[[#This Row],[ATIVIDADE]],Tabela13[ATIVIDADE],Tabela13[RISCO],"",0)) | G24: =IF(Tabela1[[#This Row],[ATIVIDADE]]="","",_xlfn.XLOOKUP(Tabela1[[#This Row],[ATIVIDADE]],Tabela13[ATIVIDADE],Tabela13[SEVERI-DADE],"",0)) | H24: =IF(Tabela1[[#This Row],[ATIVIDADE]]="","",_xlfn.XLOOKUP(Tabela1[[#This Row],[ATIVIDADE]],Tabela13[ATIVIDADE],Tabela13[PROBA-BILIDA-DE],"",0)) | I24: =IFERROR(INDEX(Tabelas!$E$5:$I$9, MATCH(Tabela1[[#This Row],[PROBA-BILIDA-DE]], Tabelas!$D$5:$D$9, 0), MATCH(Tabela1[[#This Row],[SEVERI-DADE]], Tabelas!$E$4:$I$4, 0)),"") | J24: =IF(Tabela1[[#This Row],[ATIVIDADE]]="","",_xlfn.XLOOKUP(Tabela1[[#This Row],[ATIVIDADE]],Tabela13[ATIVIDADE],Tabela13[ELIMINAÇÃO],"",0)) | K24: =IF(Tabela1[[#This Row],[ATIVIDADE]]="","",_xlfn.XLOOKUP(Tabela1[[#This Row],[ATIVIDADE]],Tabela13[ATIVIDADE],Tabela13[SUBSTITUIÇÃO],"",0)) | L24: =IF(Tabela1[[#This Row],[ATIVIDADE]]="","",_xlfn.XLOOKUP(Tabela1[[#This Row],[ATIVIDADE]],Tabela13[ATIVIDADE],Tabela13[CONTROLES DE ENGENHARIA],"",0)) | M24: =IF(Tabela1[[#This Row],[ATIVIDADE]]="","",_xlfn.XLOOKUP(Tabela1[[#This Row],[ATIVIDADE]],Tabela13[ATIVIDADE],Tabela13[SINALIZAÇÃO/ ALERTAS E/OU CONTROLE ADM],"",0)) | N24: =IF(Tabela1[[#This Row],[ATIVIDADE]]="","",_xlfn.XLOOKUP(Tabela1[[#This Row],[ATIVIDADE]],Tabela13[ATIVIDADE],Tabela13[EPI],"",0)) | O24: =IF(Tabela1[[#This Row],[ATIVIDADE]]="","",_xlfn.XLOOKUP(Tabela1[[#This Row],[ATIVIDADE]],Tabela13[ATIVIDADE],Tabela13[SEVERI-DADE ],"",0)) | P24: =IF(Tabela1[[#This Row],[ATIVIDADE]]="","",_xlfn.XLOOKUP(Tabela1[[#This Row],[ATIVIDADE]],Tabela13[ATIVIDADE],Tabela13[PROBA-BILIDA-DE ],"",0)) | Q24: =IFERROR(INDEX(Tabelas!$E$5:$I$9, MATCH(Tabela1[[#This Row],[PROBA-BILIDA-DE ]], Tabelas!$D$5:$D$9, 0), MATCH(Tabela1[[#This Row],[SEVERI-DADE ]], Tabelas!$E$4:$I$4, 0)),"") | R24: =IF(Tabela1[[#This Row],[ATIVIDADE]]="","",_xlfn.XLOOKUP(Tabela1[[#This Row],[ATIVIDADE]],Tabela13[ATIVIDADE],Tabela13[CONTROLES ESPECÍFICOS],"",0))

Sheet Croqui
I2: CROQUI | AO2: =PEX!AO2 -> SI | AS2: =PEX!AS2 -> 00012345/25H
I3: Croqui de Aterramento Temporário
AO4: Data | AS4: =PEX!H13 -> 45996
B63: Observação: Os aterramentos serão instalados/retirados no decorrer da intervenção.
B64: Quantidade Total de Aterramentos | Q64: Legenda:
F65: 6 | H65: unidades
B67: Responsável pela Intervenção: | W67: Matrícula: | AG67: Assinatura:
B68: =PEX!H8 -> DOUGLAS HIGINO DOS SANTOS | W68: =PEX!AG8 -> 268186

Sheet Controle P.Crítico
D2: VERIFICAÇÃO | J2: =PEX!AO2 -> SI | K2: =PEX!AS2 -> 00012345/25H
D3: Controle de Pontos Críticos da Intervenção
J4: DATA | K4: =PEX!H13 -> 45996
B6: Tipo do Ponto Crítico | C6: Item | D6: Ponto Crítico | E6: Responsável | F6: Verificador | G6: Controlar p/ fase? | H6: # | I6: Horário | J6: Horário fase A | K6: Horário fase B | L6: Horário fase C
B7: Segurança de Pessoas | C7: 1 | D7: CONFIRMAR AUSÊNCIA DE TENSÃO | G7: FALSE | H7: =IF(AND(Tabela138[[#This Row],[Item]]<>"",LEN(Tabela138[[#This Row],[Item]])<3),1,"") -> 1 | I7: ="___:___" -> ___:___ | J7: ="___:___" -> ___:___ | K7: ="___:___" -> ___:___ | L7: ="___:___" -> ___:___
C8: =IF(B8<>"", IF(IFERROR(FIND(".", C7),0)>0, VALUE(LEFT(C7, FIND(".", C7)-1))+1, VALUE(C7)+1), IF(IFERROR(FIND(".", C7),0)>0, LEFT(C7, FIND(".", C7)) & (VALUE(RIGHT(C7, LEN(C7) - FIND(".", C7)))+1), C7 & ".1" ) ) -> 1.1 | D8: Usar bastão isolante para aproximar detector a ponto energizado e testar funcionamento | G8: FALSE | H8: =IF(AND(Tabela138[[#This Row],[Item]]<>"",LEN(Tabela138[[#This Row],[Item]])<3),1,"") | I8: ="___:___" -> ___:___ | J8: ="___:___" -> ___:___ | K8: ="___:___" -> ___:___ | L8: ="___:___" -> ___:___
C9: =IF(B9<>"", IF(IFERROR(FIND(".", C8),0)>0, VALUE(LEFT(C8, FIND(".", C8)-1))+1, VALUE(C8)+1), IF(IFERROR(FIND(".", C8),0)>0, LEFT(C8, FIND(".", C8)) & (VALUE(RIGHT(C8, LEN(C8) - FIND(".", C8)))+1), C8 & ".1" ) ) -> 1.2 | D9: Aproximar detector a cada condutor das fases a serem aterradas | G9: TRUE | H9: =IF(AND(Tabela138[[#This Row],[Item]]<>"",LEN(Tabela138[[#This Row],[Item]])<3),1,"") | I9: ="___:___" -> ___:___ | J9: ="___:___" -> ___:___ | K9: ="___:___" -> ___:___ | L9: ="___:___" -> ___:___
C10: =IF(B10<>"", IF(IFERROR(FIND(".", C9),0)>0, VALUE(LEFT(C9, FIND(".", C9)-1))+1, VALUE(C9)+1), IF(IFERROR(FIND(".", C9),0)>0, LEFT(C9, FIND(".", C9)) & (VALUE(RIGHT(C9, LEN(C9) - FIND(".", C9)))+1), C9 & ".1" ) ) -> 1.3 | D10: Reaproximar detector a ponto energizado para reconfirmar funcionamento | G10: FALSE | H10: =IF(AND(Tabela138[[#This Row],[Item]]<>"",LEN(Tabela138[[#This Row],[Item]])<3),1,"") | I10: ="___:___" -> ___:___ | J10: ="___:___" -> ___:___ | K10: ="___:___" -> ___:___ | L10: ="___:___" -> ___:___
B11: Segurança de Pessoas / Sistema | C11: =IF(B11<>"", IF(IFERROR(FIND(".", C10),0)>0, VALUE(LEFT(C10, FIND(".", C10)-1))+1, VALUE(C10)+1), IF(IFERROR(FIND(".", C10),0)>0, LEFT(C10, FIND(".", C10)) & (VALUE(RIGHT(C10, LEN(C10) - FIND(".", C10)))+1), C10 & ".1" ) ) -> 2 | D11: INSTALAÇÃO DO ATERRAMENTO MÓVEL TEMPORÁRIO | G11: FALSE | H11: =IF(AND(Tabela138[[#This Row],[Item]]<>"",LEN(Tabela138[[#This Row],[Item]])<3),1,"") -> 1 | I11: ="___:___" -> ___:___ | J11: ="___:___" -> ___:___ | K11: ="___:___" -> ___:___ | L11: ="___:___" -> ___:___
C12: =IF(B12<>"", IF(IFERROR(FIND(".", C11),0)>0, VALUE(LEFT(C11, FIND(".", C11)-1))+1, VALUE(C11)+1), IF(IFERROR(FIND(".", C11),0)>0, LEFT(C11, FIND(".", C11)) & (VALUE(RIGHT(C11, LEN(C11) - FIND(".", C11)))+1), C11 & ".1" ) ) -> 2.1 | D12: Limpar contatos e conectar grampos e todos os cabos à malha de terra garantindo bom aperto | G12: FALSE | H12: =IF(AND(Tabela138[[#This Row],[Item]]<>"",LEN(Tabela138[[#This Row],[Item]])<3),1,"") | I12: ="___:___" -> ___:___ | J12: ="___:___" -> ___:___ | K12: ="___:___" -> ___:___ | L12: ="___:___" -> ___:___
C13: =IF(B13<>"", IF(IFERROR(FIND(".", C12),0)>0, VALUE(LEFT(C12, FIND(".", C12)-1))+1, VALUE(C12)+1), IF(IFERROR(FIND(".", C12),0)>0, LEFT(C12, FIND(".", C12)) & (VALUE(RIGHT(C12, LEN(C12) - FIND(".", C12)))+1), C12 & ".1" ) ) -> 2.2 | D13: Confirmar bastões isolantes aprovados no teste de isolação GO-MN-LT-M.026 | G13: FALSE | H13: =IF(AND(Tabela138[[#This Row],[Item]]<>"",LEN(Tabela138[[#This Row],[Item]])<3),1,"") | I13: ="___:___" -> ___:___ | J13: ="___:___" -> ___:___ | K13: ="___:___" -> ___:___ | L13: ="___:___" -> ___:___
C14: =IF(B14<>"", IF(IFERROR(FIND(".", C13),0)>0, VALUE(LEFT(C13, FIND(".", C13)-1))+1, VALUE(C13)+1), IF(IFERROR(FIND(".", C13),0)>0, LEFT(C13, FIND(".", C13)) & (VALUE(RIGHT(C13, LEN(C13) - FIND(".", C13)))+1), C13 & ".1" ) ) -> 2.3 | D14: Primeiro aterramento: Levar conjunto com bastão e aproximar ao ponto sem contato direto | G14: TRUE | H14: =IF(AND(Tabela138[[#This Row],[Item]]<>"",LEN(Tabela138[[#This Row],[Item]])<3),1,"") | I14: ="___:___" -> ___:___ | J14: ="___:___" -> ___:___ | K14: ="___:___" -> ___:___ | L14: ="___:___" -> ___:___
C15: =IF(B15<>"", IF(IFERROR(FIND(".", C14),0)>0, VALUE(LEFT(C14, FIND(".", C14)-1))+1, VALUE(C14)+1), IF(IFERROR(FIND(".", C14),0)>0, LEFT(C14, FIND(".", C14)) & (VALUE(RIGHT(C14, LEN(C14) - FIND(".", C14)))+1), C14 & ".1" ) ) -> 2.4 | D15: Primeiro aterramento: Conectar ao barramento pulo ou equipamento conforme SI e croqui | G15: TRUE | H15: =IF(AND(Tabela138[[#This Row],[Item]]<>"",LEN(Tabela138[[#This Row],[Item]])<3),1,"") | I15: ="___:___" -> ___:___ | J15: ="___:___" -> ___:___ | K15: ="___:___" -> ___:___ | L15: ="___:___" -> ___:___
C16: =IF(B16<>"", IF(IFERROR(FIND(".", C15),0)>0, VALUE(LEFT(C15, FIND(".", C15)-1))+1, VALUE(C15)+1), IF(IFERROR(FIND(".", C15),0)>0, LEFT(C15, FIND(".", C15)) & (VALUE(RIGHT(C15, LEN(C15) - FIND(".", C15)))+1), C15 & ".1" ) ) -> 2.5 | D16: Segundo aterramento: Levar conjunto com bastão e aproximar ao ponto sem contato direto | G16: TRUE | H16: =IF(AND(Tabela138[[#This Row],[Item]]<>"",LEN(Tabela138[[#This Row],[Item]])<3),1,"") | I16: ="___:___" -> ___:___ | J16: ="___:___" -> ___:___ | K16: ="___:___" -> ___:___ | L16: ="___:___" -> ___:___
C17: =IF(B17<>"", IF(IFERROR(FIND(".", C16),0)>0, VALUE(LEFT(C16, FIND(".", C16)-1))+1, VALUE(C16)+1), IF(IFERROR(FIND(".", C16),0)>0, LEFT(C16, FIND(".", C16)) & (VALUE(RIGHT(C16, LEN(C16) - FIND(".", C16)))+1), C16 & ".1" ) ) -> 2.6 | D17: Segundo aterramento: Conectar ao barramento pulo ou equipamento conforme SI e croqui | G17: TRUE | H17: =IF(AND(Tabela138[[#This Row],[Item]]<>"",LEN(Tabela138[[#This Row],[Item]])<3),1,"") | I17: ="___:___" -> ___:___ | J17: ="___:___" -> ___:___ | K17: ="___:___" -> ___:___ | L17: ="___:___" -> ___:___
C18: =IF(B18<>"", IF(IFERROR(FIND(".", C17),0)>0, VALUE(LEFT(C17, FIND(".", C17)-1))+1, VALUE(C17)+1), IF(IFERROR(FIND(".", C17),0)>0, LEFT(C17, FIND(".", C17)) & (VALUE(RIGHT(C17, LEN(C17) - FIND(".", C17)))+1), C17 & ".1" ) ) -> 2.7 | D18: Terceiro aterramento: Levar conjunto com bastão e aproximar ao ponto sem contato direto | G18: TRUE | H18: =IF(AND(Tabela138[[#This Row],[Item]]<>"",LEN(Tabela138[[#This Row],[Item]])<3),1,"") | I18: ="___:___" -> ___:___ | J18: ="___:___" -> ___:___ | K18: ="___:___" -> ___:___ | L18: ="___:___" -> ___:___
C19: =IF(B19<>"", IF(IFERROR(FIND(".", C18),0)>0, VALUE(LEFT(C18, FIND(".", C18)-1))+1, VALUE(C18)+1), IF(IFERROR(FIND(".", C18),0)>0, LEFT(C18, FIND(".", C18)) & (VALUE(RIGHT(C18, LEN(C18) - FIND(".", C18)))+1), C18 & ".1" ) ) -> 2.8 | D19: Terceiro aterramento: Conectar ao barramento pulo ou equipamento conforme SI e croqui | G19: TRUE | H19: =IF(AND(Tabela138[[#This Row],[Item]]<>"",LEN(Tabela138[[#This Row],[Item]])<3),1,"") | I19: ="___:___" -> ___:___ | J19: ="___:___" -> ___:___ | K19: ="___:___" -> ___:___ | L19: ="___:___" -> ___:___
B20: Segurança de Pessoas | C20: =IF(B20<>"", IF(IFERROR(FIND(".", C19),0)>0, VALUE(LEFT(C19, FIND(".", C19)-1))+1, VALUE(C19)+1), IF(IFERROR(FIND(".", C19),0)>0, LEFT(C19, FIND(".", C19)) & (VALUE(RIGHT(C19, LEN(C19) - FIND(".", C19)))+1), C19 & ".1" ) ) -> 3 | D20: FIXAÇÃO DA ESCADA E ESCALADA | G20: FALSE | H20: =IF(AND(Tabela138[[#This Row],[Item]]<>"",LEN(Tabela138[[#This Row],[Item]])<3),1,"") -> 1 | I20: ="___:___" -> ___:___ | J20: ="___:___" -> ___:___ | K20: ="___:___" -> ___:___ | L20: ="___:___" -> ___:___
C21: =IF(B21<>"", IF(IFERROR(FIND(".", C20),0)>0, VALUE(LEFT(C20, FIND(".", C20)-1))+1, VALUE(C20)+1), IF(IFERROR(FIND(".", C20),0)>0, LEFT(C20, FIND(".", C20)) & (VALUE(RIGHT(C20, LEN(C20) - FIND(".", C20)))+1), C20 & ".1" ) ) -> 3.1 | D21: Posicionar escada em superfície firme e nivelada garantindo ângulo adequado de aproximadamente 75° | G21: TRUE | H21: =IF(AND(Tabela138[[#This Row],[Item]]<>"",LEN(Tabela138[[#This Row],[Item]])<3),1,"") | I21: ="___:___" -> ___:___ | J21: ="___:___" -> ___:___ | K21: ="___:___" -> ___:___ | L21: ="___:___" -> ___:___
C22: =IF(B22<>"", IF(IFERROR(FIND(".", C21),0)>0, VALUE(LEFT(C21, FIND(".", C21)-1))+1, VALUE(C21)+1), IF(IFERROR(FIND(".", C21),0)>0, LEFT(C21, FIND(".", C21)) & (VALUE(RIGHT(C21, LEN(C21) - FIND(".", C21)))+1), C21 & ".1" ) ) -> 3.2 | D22: Fixar escada com cordas ou dispositivos de ancoragem para evitar deslocamento durante a subida | G22: TRUE | H22: =IF(AND(Tabela138[[#This Row],[Item]]<>"",LEN(Tabela138[[#This Row],[Item]])<3),1,"") | I22: ="___:___" -> ___:___ | J22: ="___:___" -> ___:___ | K22: ="___:___" -> ___:___ | L22: ="___:___" -> ___:___
C23: =IF(B23<>"", IF(IFERROR(FIND(".", C22),0)>0, VALUE(LEFT(C22, FIND(".", C22)-1))+1, VALUE(C22)+1), IF(IFERROR(FIND(".", C22),0)>0, LEFT(C22, FIND(".", C22)) & (VALUE(RIGHT(C22, LEN(C22) - FIND(".", C22)))+1), C22 & ".1" ) ) -> 3.3 | D23: Utilizar cinto de segurança e talabarte para proteção contra queda durante a escalada | G23: TRUE | H23: =IF(AND(Tabela138[[#This Row],[Item]]<>"",LEN(Tabela138[[#This Row],[Item]])<3),1,"") | I23: ="___:___" -> ___:___ | J23: ="___:___" -> ___:___ | K23: ="___:___" -> ___:___ | L23: ="___:___" -> ___:___
B24: Segurança de Pessoas / Sistema | C24: =IF(B24<>"", IF(IFERROR(FIND(".", C23),0)>0, VALUE(LEFT(C23, FIND(".", C23)-1))+1, VALUE(C23)+1), IF(IFERROR(FIND(".", C23),0)>0, LEFT(C23, FIND(".", C23)) & (VALUE(RIGHT(C23, LEN(C23) - FIND(".", C23)))+1), C23 & ".1" ) ) -> 4 | D24: REMOVER ATERRAMENTO MÓVEL TEMPORÁRIO | G24: FALSE | H24: =IF(AND(Tabela138[[#This Row],[Item]]<>"",LEN(Tabela138[[#This Row],[Item]])<3),1,"") -> 1 | I24: ="___:___" -> ___:___ | J24: ="___:___" -> ___:___ | K24: ="___:___" -> ___:___ | L24: ="___:___" -> ___:___
C25: =IF(B25<>"", IF(IFERROR(FIND(".", C24),0)>0, VALUE(LEFT(C24, FIND(".", C24)-1))+1, VALUE(C24)+1), IF(IFERROR(FIND(".", C24),0)>0, LEFT(C24, FIND(".", C24)) & (VALUE(RIGHT(C24, LEN(C24) - FIND(".", C24)))+1), C24 & ".1" ) ) -> 4.1 | D25: Avisar equipe antes de iniciar retirada do aterramento temporário | G25: FALSE | H25: =IF(AND(Tabela138[[#This Row],[Item]]<>"",LEN(Tabela138[[#This Row],[Item]])<3),1,"") | I25: ="___:___" -> ___:___ | J25: ="___:___" -> ___:___ | K25: ="___:___" -> ___:___ | L25: ="___:___" -> ___:___
C26: =IF(B26<>"", IF(IFERROR(FIND(".", C25),0)>0, VALUE(LEFT(C25, FIND(".", C25)-1))+1, VALUE(C25)+1), IF(IFERROR(FIND(".", C25),0)>0, LEFT(C25, FIND(".", C25)) & (VALUE(RIGHT(C25, LEN(C25) - FIND(".", C25)))+1), C25 & ".1" ) ) -> 4.2 | D26: Primeiro aterramento: Usar bastão para desconectar do barramento/pulo/equipamento | G26: TRUE | H26: =IF(AND(Tabela138[[#This Row],[Item]]<>"",LEN(Tabela138[[#This Row],[Item]])<3),1,"") | I26: ="___:___" -> ___:___ | J26: ="___:___" -> ___:___ | K26: ="___:___" -> ___:___ | L26: ="___:___" -> ___:___
C27: =IF(B27<>"", IF(IFERROR(FIND(".", C26),0)>0, VALUE(LEFT(C26, FIND(".", C26)-1))+1, VALUE(C26)+1), IF(IFERROR(FIND(".", C26),0)>0, LEFT(C26, FIND(".", C26)) & (VALUE(RIGHT(C26, LEN(C26) - FIND(".", C26)))+1), C26 & ".1" ) ) -> 4.3 | D27: Primeiro aterramento: Baixar cabo ao solo sem contato e longe de pontos energizados | G27: TRUE | H27: =IF(AND(Tabela138[[#This Row],[Item]]<>"",LEN(Tabela138[[#This Row],[Item]])<3),1,"") | I27: ="___:___" -> ___:___ | J27: ="___:___" -> ___:___ | K27: ="___:___" -> ___:___ | L27: ="___:___" -> ___:___
C28: =IF(B28<>"", IF(IFERROR(FIND(".", C27),0)>0, VALUE(LEFT(C27, FIND(".", C27)-1))+1, VALUE(C27)+1), IF(IFERROR(FIND(".", C27),0)>0, LEFT(C27, FIND(".", C27)) & (VALUE(RIGHT(C27, LEN(C27) - FIND(".", C27)))+1), C27 & ".1" ) ) -> 4.4 | D28: Segundo aterramento: Usar bastão para desconectar do barramento/pulo/equipamento | G28: TRUE | H28: =IF(AND(Tabela138[[#This Row],[Item]]<>"",LEN(Tabela138[[#This Row],[Item]])<3),1,"") | I28: ="___:___" -> ___:___ | J28: ="___:___" -> ___:___ | K28: ="___:___" -> ___:___ | L28: ="___:___" -> ___:___
C29: =IF(B29<>"", IF(IFERROR(FIND(".", C28),0)>0, VALUE(LEFT(C28, FIND(".", C28)-1))+1, VALUE(C28)+1), IF(IFERROR(FIND(".", C28),0)>0, LEFT(C28, FIND(".", C28)) & (VALUE(RIGHT(C28, LEN(C28) - FIND(".", C28)))+1), C28 & ".1" ) ) -> 4.5 | D29: Segundo aterramento: Baixar cabo ao solo sem contato e longe de pontos energizados | G29: TRUE | H29: =IF(AND(Tabela138[[#This Row],[Item]]<>"",LEN(Tabela138[[#This Row],[Item]])<3),1,"") | I29: ="___:___" -> ___:___ | J29: ="___:___" -> ___:___ | K29: ="___:___" -> ___:___ | L29: ="___:___" -> ___:___
C30: =IF(B30<>"", IF(IFERROR(FIND(".", C29),0)>0, VALUE(LEFT(C29, FIND(".", C29)-1))+1, VALUE(C29)+1), IF(IFERROR(FIND(".", C29),0)>0, LEFT(C29, FIND(".", C29)) & (VALUE(RIGHT(C29, LEN(C29) - FIND(".", C29)))+1), C29 & ".1" ) ) -> 4.6 | D30: Terceiro aterramento: Usar bastão para desconectar do barramento/pulo/equipamento | G30: TRUE | H30: =IF(AND(Tabela138[[#This Row],[Item]]<>"",LEN(Tabela138[[#This Row],[Item]])<3),1,"") | I30: ="___:___" -> ___:___ | J30: ="___:___" -> ___:___ | K30: ="___:___" -> ___:___ | L30: ="___:___" -> ___:___
C31: =IF(B31<>"", IF(IFERROR(FIND(".", C30),0)>0, VALUE(LEFT(C30, FIND(".", C30)-1))+1, VALUE(C30)+1), IF(IFERROR(FIND(".", C30),0)>0, LEFT(C30, FIND(".", C30)) & (VALUE(RIGHT(C30, LEN(C30) - FIND(".", C30)))+1), C30 & ".1" ) ) -> 4.7 | D31: Terceiro aterramento: Baixar cabo ao solo sem contato e longe de pontos energizados | G31: TRUE | H31: =IF(AND(Tabela138[[#This Row],[Item]]<>"",LEN(Tabela138[[#This Row],[Item]])<3),1,"") | I31: ="___:___" -> ___:___ | J31: ="___:___" -> ___:___ | K31: ="___:___" -> ___:___ | L31: ="___:___" -> ___:___
C32: =IF(B32<>"", IF(IFERROR(FIND(".", C31),0)>0, VALUE(LEFT(C31, FIND(".", C31)-1))+1, VALUE(C31)+1), IF(IFERROR(FIND(".", C31),0)>0, LEFT(C31, FIND(".", C31)) & (VALUE(RIGHT(C31, LEN(C31) - FIND(".", C31)))+1), C31 & ".1" ) ) -> 4.8 | D32: Retirar grampo de terra somente após todos os cabos desconectados da parte superior | G32: FALSE | H32: =IF(AND(Tabela138[[#This Row],[Item]]<>"",LEN(Tabela138[[#This Row],[Item]])<3),1,"") | I32: ="___:___" -> ___:___ | J32: ="___:___" -> ___:___ | K32: ="___:___" -> ___:___ | L32: ="___:___" -> ___:___
